<?xml version="1.0" ?>
<!-- =================================================================================== -->
<!-- |    This document was autogenerated by xacro from prsg2_jay_description.xacro    | -->
<!-- |    EDITING THIS FILE BY HAND IS NOT RECOMMENDED                                 | -->
<!-- =================================================================================== -->
<robot name="prsg2_robot" xmlns:xacro="http://www.ros.org/wiki/xacro">
  <!-- The robot description -->
  <link name="base_link">
    <collision>
      <origin rpy="0 0 0" xyz="0 0 0.047"/>
      <geometry>
        <cylinder length="0.006" radius="0.1143"/>
      </geometry>
    </collision>
    <visual>
      <origin rpy="0 0 0" xyz="0 0 0.047"/>
      <geometry>
        <cylinder length="0.006" radius="0.1143"/>
      </geometry>
      <material name="color_0.5_0.5_0.5_{$a}">
        <color rgba="0.5 0.5 0.5 0.3"/>
      </material>
    </visual>
    <inertial>
      <origin rpy="0 0 0" xyz="0 0 0.047"/>
      <mass value="1"/>
      <inertia ixx="100" ixy="0" ixz="0" iyy="100" iyz="0" izz="100"/>
    </inertial>
  </link>
  <link name="left_wheel_link">
    <collision>
      <origin rpy="1.57079632679 0 0" xyz="0 0 0"/>
      <geometry>
        <cylinder length="0.008" radius="0.03"/>
      </geometry>
    </collision>
    <visual>
      <origin rpy="1.57079632679 0 0" xyz="0 0 0"/>
      <geometry>
        <cylinder length="0.008" radius="0.03"/>
      </geometry>
      <material name="color_0.4_0.4_1.0_{$a}">
        <color rgba="0.4 0.4 1.0 1.0"/>
      </material>
    </visual>
    <inertial>
      <origin rpy="1.57079632679 0 0" xyz="0 0 0"/>
      <mass value="1"/>
      <inertia ixx="100" ixy="0" ixz="0" iyy="100" iyz="0" izz="100"/>
    </inertial>
  </link>
  <link name="left_wheel_link_ray_link"/>
  <joint name="base_link_to_left_wheel_link_ray" type="fixed">
    <parent link="base_link"/>
    <child link="left_wheel_link_ray_link"/>
    <origin rpy="0 0 1.57079632679"/>
  </joint>
  <joint name="left_wheel_link_ray_to_left_wheel_link" type="fixed">
    <parent link="left_wheel_link_ray_link"/>
    <child link="left_wheel_link"/>
    <origin rpy="0 0 -1.57079632679" xyz="0.1025 0 0.03"/>
  </joint>
  <link name="right_wheel_link">
    <collision>
      <origin rpy="1.57079632679 0 0" xyz="0 0 0"/>
      <geometry>
        <cylinder length="0.008" radius="0.03"/>
      </geometry>
    </collision>
    <visual>
      <origin rpy="1.57079632679 0 0" xyz="0 0 0"/>
      <geometry>
        <cylinder length="0.008" radius="0.03"/>
      </geometry>
      <material name="color_0.4_0.4_1.0_{$a}">
        <color rgba="0.4 0.4 1.0 1.0"/>
      </material>
    </visual>
    <inertial>
      <origin rpy="1.57079632679 0 0" xyz="0 0 0"/>
      <mass value="1"/>
      <inertia ixx="100" ixy="0" ixz="0" iyy="100" iyz="0" izz="100"/>
    </inertial>
  </link>
  <link name="right_wheel_link_ray_link"/>
  <joint name="base_link_to_right_wheel_link_ray" type="fixed">
    <parent link="base_link"/>
    <child link="right_wheel_link_ray_link"/>
    <origin rpy="0 0 -1.57079632679"/>
  </joint>
  <joint name="right_wheel_link_ray_to_right_wheel_link" type="fixed">
    <parent link="right_wheel_link_ray_link"/>
    <child link="right_wheel_link"/>
    <origin rpy="0 0 1.57079632679" xyz="0.1025 0 0.03"/>
  </joint>
  <link name="front_caster_link">
    <collision>
      <origin rpy="0 0 0"/>
      <geometry>
        <sphere radius="0.009"/>
      </geometry>
    </collision>
    <visual>
      <origin rpy="0 0 0"/>
      <geometry>
        <sphere radius="0.009"/>
      </geometry>
      <material name="color_1.0_1.0_1.0_{$a}">
        <color rgba="1.0 1.0 1.0 1.0"/>
      </material>
    </visual>
    <inertial>
      <origin rpy="0 0 0" xyz="0 0 0"/>
      <mass value="0.1"/>
      <inertia ixx="10" ixy="0" ixz="0" iyy="10" iyz="0" izz="10"/>
    </inertial>
  </link>
  <link name="front_caster_link_ray_link"/>
  <joint name="base_link_to_front_caster_link_ray" type="fixed">
    <parent link="base_link"/>
    <child link="front_caster_link_ray_link"/>
    <origin rpy="0 0 0.0"/>
  </joint>
  <joint name="front_caster_link_ray_to_front_caster_link" type="fixed">
    <parent link="front_caster_link_ray_link"/>
    <child link="front_caster_link"/>
    <origin rpy="0 0 0.0" xyz="0.1043 0 0.009"/>
  </joint>
  <link name="rear_caster_link">
    <collision>
      <origin rpy="1.57079632679 0 0"/>
      <geometry>
        <sphere radius="0.009"/>
      </geometry>
    </collision>
    <visual>
      <origin rpy="1.57079632679 0 0"/>
      <geometry>
        <sphere radius="0.009"/>
      </geometry>
      <material name="color_1.0_1.0_1.0_{$a}">
        <color rgba="1.0 1.0 1.0 1.0"/>
      </material>
    </visual>
    <inertial>
      <origin rpy="0 0 0" xyz="0 0 0"/>
      <mass value="0.1"/>
      <inertia ixx="10" ixy="0" ixz="0" iyy="10" iyz="0" izz="10"/>
    </inertial>
  </link>
  <link name="rear_caster_link_ray_link"/>
  <joint name="base_link_to_rear_caster_link_ray" type="fixed">
    <parent link="base_link"/>
    <child link="rear_caster_link_ray_link"/>
    <origin rpy="0 0 -3.14159265359"/>
  </joint>
  <joint name="rear_caster_link_ray_to_rear_caster_link" type="fixed">
    <parent link="rear_caster_link_ray_link"/>
    <child link="rear_caster_link"/>
    <origin rpy="0 0 3.14159265359" xyz="0.1043 0 0.009"/>
  </joint>
  <!-- <xacro:ir_sensor link_name="ir_left_front_link" theta="${37.4 * degree}" />  -->
  <!-- <xacro:ir_sensor link_name="ir_right_front_link" theta="${-27.8 * degree}" />  -->
  <link name="ir_left_front_servo_link">
    <collision>
      <origin rpy="0 0 0" xyz="0 0 0"/>
      <geometry>
        <!-- platter on which IR sensor sits: -->
        <!-- length might be z-offset + thickness instead -->
        <cylinder length="0.002" radius="0.015"/>
      </geometry>
    </collision>
    <visual>
      <origin rpy="0 0 0" xyz="0 0 0"/>
      <geometry>
        <!-- platter on which IR sensor sits: -->
        <!-- length might be z-offset + thickness instead -->
        <cylinder length="0.002" radius="0.015"/>
      </geometry>
    </visual>
    <inertial>
      <origin rpy="0 0 0" xyz="0 0 0"/>
      <mass value="0.1"/>
      <inertia ixx="10" ixy="0" ixz="0" iyy="10" iyz="0" izz="10"/>
    </inertial>
  </link>
  <link name="ir_left_front_servo_link_ray_link"/>
  <joint name="base_link_to_ir_left_front_servo_link_ray" type="fixed">
    <parent link="base_link"/>
    <child link="ir_left_front_servo_link_ray_link"/>
    <origin rpy="0 0 0.652753140246"/>
  </joint>
  <joint name="ir_left_front_servo_link_ray_to_ir_left_front_servo_link" type="revolute">
    <parent link="ir_left_front_servo_link_ray_link"/>
    <child link="ir_left_front_servo_link"/>
    <origin rpy="0 0 -0.785398163397" xyz="0.1123 0 0.069"/>
    <!-- axis of servo rotation: -->
    <axis xyz="0 0 1"/>
    <limit effort="1" lower="0" upper="3.14159265359" velocity="1"/>
  </joint>
  <joint name="ir_left_front_link" type="fixed">
    <parent link="ir_left_front_servo_link"/>
    <child link="ir_left_front_link"/>
    <origin rpy="0 0 0" xyz="0 0 0"/>
    <!-- axis of servo rotation: -->
    <axis xyz="0 0 1"/>
  </joint>
  <link name="ir_right_front_servo_link">
    <collision>
      <origin rpy="0 0 0" xyz="0 0 0"/>
      <geometry>
        <!-- platter on which IR sensor sits: -->
        <!-- length might be z-offset + thickness instead -->
        <cylinder length="0.002" radius="0.015"/>
      </geometry>
    </collision>
    <visual>
      <origin rpy="0 0 0" xyz="0 0 0"/>
      <geometry>
        <!-- platter on which IR sensor sits: -->
        <!-- length might be z-offset + thickness instead -->
        <cylinder length="0.002" radius="0.015"/>
      </geometry>
    </visual>
    <inertial>
      <origin rpy="0 0 0" xyz="0 0 0"/>
      <mass value="0.1"/>
      <inertia ixx="10" ixy="0" ixz="0" iyy="10" iyz="0" izz="10"/>
    </inertial>
  </link>
  <link name="ir_right_front_servo_link_ray_link"/>
  <joint name="base_link_to_ir_right_front_servo_link_ray" type="fixed">
    <parent link="base_link"/>
    <child link="ir_right_front_servo_link_ray_link"/>
    <origin rpy="0 0 -0.485201532054"/>
  </joint>
  <joint name="ir_right_front_servo_link_ray_to_ir_right_front_servo_link" type="revolute">
    <parent link="ir_right_front_servo_link_ray_link"/>
    <child link="ir_right_front_servo_link"/>
    <origin rpy="0 0 0.523598775598" xyz="0.1123 0 0.069"/>
    <!-- axis of servo rotation: -->
    <axis xyz="0 0 1"/>
    <limit effort="1" lower="0" upper="3.14159265359" velocity="1"/>
  </joint>
  <joint name="ir_right_front_link" type="fixed">
    <parent link="ir_right_front_servo_link"/>
    <child link="ir_right_front_link"/>
    <origin rpy="0 0 0" xyz="0 0 0"/>
    <!-- axis of servo rotation: -->
    <axis xyz="0 0 1"/>
  </joint>
</robot>

